Workbook

Sheet README
A1: BSI (BRIS) integrated valuation model v11.2
A2: Valuation date 16-Oct-2026 | price Rp 1,095 | units Rp bn unless stated | template: Quick FM (Alip), fixed and extended by the team
A4: Colour code
A5: Blue text | B5: Input you can change
A6: Black text | B6: Formula
A7: Green text | B7: Link to another sheet
A8: Orange fill | B8: Input still estimated (see Input_Register)
A10: Sheet | B10: Role | C10: What it holds | D10: Open items
A11: Dashboard | B11: Output | C11: One-page view: verdict, cost of equity, story to numbers, methods, scenarios, checks, where to change what | D11: Start here
A12: Sheet1 | B12: Engine | C12: Inputs, income statement, balance sheet, cash flow, capital, DDM, residual income, 12m PT, scenarios, tornado, peers, charts | D12: Scenario and tornado blocks are static snapshots (flags E444, E455)
A13: Valuation_Checks | B13: Valuation | C13: Banking FCFE, justified and exit P/B, Ke x terminal-ROE-spread grid | D13: Cross-checks only
A14: Charts | B14: Output | C14: Chart data blocks and the 11 model charts (moved out of Sheet1)
A15: Terminal_ROE | B15: Valuation | C15: Evidence for terminal ROE = Ke + spread, scenario spreads, live sensitivity
A16: Beta_Evidence | B16: Valuation | C16: Observed betas, Blume adjustment, lambda cross-check, beta sensitivity of PT (static) | D16: Confirm raw-beta source and period with Alip
A17: Prob_Justification | B17: Valuation | C17: Evidence tally behind the Bear / Base / Bull probabilities | D17: Weights are judgement
A18: Damodaran_Audit | B18: Check | C18: Structural checks against Damodaran bank valuation; BRIS P/B history
A19: Driver_Check | B19: Evidence | C19: Forecast drivers vs history and 1H26 run-rate | D19: Settle financing growth
A20: CF_Direct | B20: Evidence | C20: Direct cash flow FY21A-FY25A as reported
A21: Input_Register | B21: Evidence | C21: Status and source of every market input and estimate | D21: Peer 16-Oct closes, 52-week high, sell-side targets
A22: Beta / Returns / Prices | B22: Data | C22: Monthly closes and regression beta vs IHSG
A23: Change_Log | B23: Admin | C23: Version history
A25: Model notes (moved from Sheet1 section 7)
A26: Orange cells = estimates (BS detail, debt tranches, fixed assets, rates, market inputs) -> replace via research pass; model recalculates.
A27: Half-year memo (cols T:V): Jun-25A, Jun-26A and implied 2H26E. Quarterly split not built: only 1H26 flows disclosed in the source decks.
A28: FY25 deck prints operating income 25,279; NMI + fee-based = 25,937 and PPOP 12,365 ties to 25,937 -> model uses 25,937.
A29: Hist NIM (reported) vs model NIM differ by definition (earning-asset base); gap held flat in forecast (S4).
A30: Dividends paid in year t = payout x NI of year t-1. Policy payout 15% FY23-24; FY25 payout pending 2026 RUPST.
A31: Scenario summary (4h) and tornado (4i) remain static values (regenerated in v4.0); staleness flags in E471 and E482 show STALE if inputs change after the snapshot.
A32: Rights issue (up to 6.8bn shares, EGM 6-Nov-26, Q1-27): per-share values are per EXISTING share assuming pro-rata subscription (net distribution = dividends - subscription). Issue price undisclosed (placeholder).
A33: FY21A: income statement mapped to deck presentation (wadiah bonus 120 moved out of overhead into PSE / fee, as in FY22 deck vs audited). FY21 personnel/promotion split, segment balances (Rp0.1tn rounding) and DPK split are ESTIMATES (orange). NIM, cost of funds, yield and cost of credit not available for FY21: left blank.
A34: FY31-35E: drivers faded/held (financing growth fades to 5.0/6.5/8.0%, fee growth to 5/7/9%, other ratios held at FY30E). Payout ramps toward sustainable level (1-g/ROE) as growth slows - JUDGMENT. Sukuk rolled 1:1. No new equity raise after the 2027 rights issue.
A35: Remaining non-primary inputs: 52-week high, sell-side targets, peer 16-Oct closes. See Input_Register.

Sheet Dashboard
A1: BSI (BRIS) - Valuation dashboard
A2: Live links (green) to Sheet1 and supporting sheets; section 5 is a static scenario snapshot. Rp per share unless stated. The rating is the mechanical output of the +15% / -10% rule, not the team recommendation.
A4: 1. Recommendation (mechanical)
A5: Rating (> +15% BUY, < -10% SELL, else HOLD) | B5: =Sheet1!E408 -> BUY
A6: Current price, close 16-Oct-26 | B6: =Sheet1!E20 -> 1095 | H6: BSI IR historical prices
A7: Value today: intrinsic (DDM = RI) / relative / blended | B7: =Sheet1!E402 -> 2019.8393 | C7: =Sheet1!E411 -> 1142.2663 | D7: =(1-Sheet1!E29)*Sheet1!E402+Sheet1!E29*Sheet1!E411 -> 1727.315 | H7: Blend weight on relative = Sheet1 E29
A8: 12-month target price (blended) | B8: =Sheet1!E406 -> 1881.1248 | H8: Each value rolled forward 12 months at Ke, less dividends
A9: Upside to 12-month target price | B9: =Sheet1!E407 -> 0.71792219
A10: Probability-weighted 12-month target price | B10: =Sheet1!H439 -> 1854.5971 | H10: Static snapshot; weights in Prob_Justification
A11: Master model check | B11: =Sheet1!E420 -> OK | H11: OK = every integrity test passes
A13: 2. Cost of equity, terminal assumptions and weights
A14: Risk-free rate, IDR (10Y yield less default spread) | B14: =Sheet1!E24 -> 0.0556
A15: Beta: raw (selected) / Blume-adjusted year 1 | B15: =Beta_Evidence!B39 -> 0.64 | C15: =Sheet1!E26 -> 0.7588 | H15: Choice in Beta_Evidence B38; converges to 1.0 by FY35E
A16: ERP incl. country risk / country risk premium (added in full) | B16: =Sheet1!E25 -> 0.0669 | C16: =Beta_Evidence!B17 -> 0.0246 | H16: Lambda approach, Beta_Evidence B41
A17: Cost of equity: year 1 / stable (FY35E) | B17: =Sheet1!E34 -> 0.11229724 | C17: =Sheet1!S378 -> 0.1225
A18: Terminal growth / terminal ROE (stable Ke + spread) | B18: =Sheet1!E31 -> 0.045 | C18: =Sheet1!E382 -> 0.1425 | H18: Evidence in Terminal_ROE
A19: Weight on relative valuation in the target | B19: =Sheet1!E29 -> 0.33333333 | H19: MSCI Standalone consultation (15 Oct 2026); sensitivity in Valuation_Checks 4
A21: 3. Story to numbers | B21: FY25A | C21: FY26E | D21: FY28E | E21: FY30E | F21: FY35E
A22: Gross financing growth | B22: =Sheet1!I212/Sheet1!H212-1 -> 0.14493987 | C22: =Sheet1!J212/Sheet1!I212-1 -> 0.14380587 | D22: =Sheet1!L212/Sheet1!K212-1 -> 0.11540909 | E22: =Sheet1!N212/Sheet1!M212-1 -> 0.098190951 | F22: =Sheet1!S212/Sheet1!R212-1 -> 0.065
A23: Net profit (Rp bn) | B23: =Sheet1!I154 -> 7567.523 | C23: =Sheet1!J154 -> 8421.2868 | D23: =Sheet1!L154 -> 12070.327 | E23: =Sheet1!N154 -> 15139.179 | F23: =Sheet1!S154 -> 22490.829
A24: ROE (average equity) | B24: =Sheet1!I347 -> 0.15604034 | C24: =Sheet1!J347 -> 0.15199023 | D24: =Sheet1!L347 -> 0.15372455 | E24: =Sheet1!N347 -> 0.15271595 | F24: =Sheet1!S347 -> 0.14619715
A25: Cost-to-income ratio | B25: =Sheet1!I95 -> 0.52562269 | C25: =Sheet1!J95 -> 0.545 | D25: =Sheet1!L95 -> 0.515 | E25: =Sheet1!N95 -> 0.505 | F25: =Sheet1!S95 -> 0.505
A26: Cost of credit | B26: =Sheet1!I99 -> 0.0078916871 | C26: =Sheet1!J99 -> 0.007 | D26: =Sheet1!L99 -> 0.0075 | E26: =Sheet1!N99 -> 0.0075 | F26: =Sheet1!S99 -> 0.0075
A27: Gross NPF | B27: =Sheet1!I103 -> 0.0181 | C27: =Sheet1!J103 -> 0.0185 | D27: =Sheet1!L103 -> 0.018 | E27: =Sheet1!N103 -> 0.018 | F27: =Sheet1!S103 -> 0.018
A28: Dividend payout | B28: =Sheet1!I108 -> 0.2 | C28: =Sheet1!J108 -> 0.22 | D28: =Sheet1!L108 -> 0.27 | E28: =Sheet1!N108 -> 0.3 | F28: =Sheet1!S108 -> 0.65
A29: CAR | B29: =Sheet1!I328 -> 0.21996525 | C29: =Sheet1!J328 -> 0.22000884 | D29: =Sheet1!L328 -> 0.24758547 | E29: =Sheet1!N328 -> 0.2565125 | F29: =Sheet1!S328 -> 0.26696653
A30: BVPS (Rp) | B30: =Sheet1!I351 -> 1126.2456 | C30: =Sheet1!J351 -> 1275.9939 | D30: =Sheet1!L351 -> 1572.9793 | E30: =Sheet1!N351 -> 1977.3847 | F30: =Sheet1!S351 -> 2999.7819
A32: 4. Valuation by method (Rp per share) | B32: Dec-25 | C32: Today | D32: 12m
A33: Intrinsic: DDM = residual income (same terminal ROE) | B33: =Sheet1!E387 -> 1890.6207 | C33: =Sheet1!E402 -> 2019.8393 | D33: =AVERAGE(Sheet1!E404,Sheet1!E405) -> 2206.4988
A34: Cross-check: banking FCFE | B34: =Valuation_Checks!B5 -> 2356.9226 | C34: =Valuation_Checks!C5 -> 2526.1039 | D34: =Valuation_Checks!D5 -> 2769.6155 | H34: Valuation_Checks section 1
A35: Cross-check: justified P/B on FY26E book | B35: =Valuation_Checks!B8 -> 1736.88 | H35: Valuation_Checks section 2
A36: Cross-check: exit P/B at peer median | B36: =Valuation_Checks!B9 -> 1562.6414
A37: Relative: 70% P/B x Jun-26 book + 30% P/E x 1H26 annualised EPS | C37: =Sheet1!E411 -> 1142.2663 | D37: =Sheet1!E411*(1+Sheet1!E34)-Sheet1!E401 -> 1230.3768 | H37: P/B-implied Sheet1 E474, P/E-implied E480
A38: Target price: 2/3 intrinsic + 1/3 relative | C38: =(1-Sheet1!E29)*Sheet1!E402+Sheet1!E29*Sheet1!E411 -> 1727.315 | D38: =Sheet1!E406 -> 1881.1248
A39: Market-implied sustainable ROE at current price | B39: =Sheet1!E414 -> 0.12034991 | H39: Compare with terminal ROE in section 2
A41: 5. Scenarios (static snapshot) | B41: Bear | C41: Base | D41: Bull | E41: Prob-wtd
A42: Probability | B42: =Sheet1!E5 -> 0.29166667 | C42: =Sheet1!F5 -> 0.5 | D42: =Sheet1!G5 -> 0.20833333 | E42: =SUM(B42:D42) -> 1
A43: Net profit FY30E (Rp bn) | B43: =Sheet1!E426 -> 10838.649 | C43: =Sheet1!F426 -> 15139.179 | D43: =Sheet1!G426 -> 19313.348 | E43: =Sheet1!H426 -> 14754.476
A44: ROE FY35E | B44: =Sheet1!E429 -> 0.10620161 | C44: =Sheet1!F429 -> 0.14619715 | D44: =Sheet1!G429 -> 0.17805393 | E44: =Sheet1!H429 -> 0.14116861
A45: 12-month target price | B45: =Sheet1!E439 -> 1325.1816 | C45: =Sheet1!F439 -> 1881.1248 | D45: =Sheet1!G439 -> 2532.1125 | E45: =Sheet1!H439 -> 1854.5971
...

Sheet Sheet1
B1: PT BANK SYARIAH INDONESIA (PERSERO) TBK (IDX: BRIS)
B2: Rp bn unless stated | Blue = hardcode input | Black = formula | Green = cross-ref | Orange fill = ESTIMATE/PLACEHOLDER (replace with researched value) | Yellow = research input | Grey = forecast
B3: SCENARIO SELECTOR (1=Bear, 2=Base, 3=Bull) | C3: # | D3: Drives every live driver below | E3: 2
B4: Active scenario | E4: =CHOOSE($E$3,"Bear","Base","Bull") -> Base
B5: Scenario probability Bear / Base / Bull | C5: % | D5: Linked to sheet Prob_Justification (evidence tally). Was 25/50/25 hardcoded | E5: =Prob_Justification!$B$25 -> 0.29166667 | F5: =Prob_Justification!$B$26 -> 0.5 | G5: =Prob_Justification!$B$27 -> 0.20833333
B7: Sensitivity shocks (leave 0 for the case; used by tornado runner). Added to the live driver in every forecast year:
B8: Shock: gross margin yield (pp) | C8: pp | E8: 0
B9: Shock: cost of credit (pp) | C9: pp | E9: 0
B10: Shock: CIR (pp) | C10: pp | E10: 0
B11: Shock: financing growth, all segments (pp) | C11: pp | E11: 0
B12: Shock: fee income growth (pp) | C12: pp | E12: 0
B13: Shock: payout ratio (pp) | C13: pp | E13: 0
B14: Shock: cost of equity (pp) | C14: pp | E14: 0
B15: Shock: time-deposit rate change (pp) | C15: pp | E15: 0
B16: Data flags | E16: FY25 deck op income 25,279 vs NMI+fee 25,937 (PPOP ties to 25,937: used). Gemini cost/yield/NIM/fee/NPF tables conflict with IR decks: NOT used.
B18: 1. INPUTS
B19: 1a. Market & valuation inputs (RESEARCH - orange cells are placeholders)
B20: Current share price | C20: Rp | D20: Last trade 8-Oct-26 (journalarta); 6-Oct close 1,385 (Investing.com). Update to latest close before final run | E20: 1095
B21: Shares outstanding (pre rights issue) | C21: mn | D21: 46,129,260,138 sh at 31-Aug-26 (BSI IR/IDX) | E21: 46129.26
B22: Valuation date | C22: date | E22: 46304
B23: FY25 dividend payment date (paid in FY26) | C23: date | D23: RUPST May-26: Rp1,513.5bn, DPS 32.81, 20% payout | E23: 46178
B24: Risk-free rate, IDR (10Y INDOGB less sovereign default spread) | C24: % | D24: G24 = 10Y INDOGB 7.18% (6-Oct-26). H24 = Damodaran default spread for Baa2, 1.62% (Jan-26). Net rf = gross - spread (CRP is added once, inside the ERP) | E24: =$G$24-$H$24 -> 0.0556 | F24: gross / spread | G24: 0.0718 | H24: 0.0162
B25: Equity risk premium (Indonesia) | C25: % | D25: Damodaran Jan-26: 4.23% mature + 2.46% CRP | E25: 0.0669
B26: Beta, Blume-adjusted year 1 (raw beta chosen in Beta_Evidence B38) | C26: x | D26: Linked to Beta_Evidence B12; converges to 1.0 by FY35E when Beta_Evidence B42 = 1 | E26: =Beta_Evidence!$B$12 -> 0.7588
B27: Size / liquidity premium | C27: % | D27: Set to 0 in v4.0 (was +1.0%, pure judgment, would double count the CRP). Kept as a toggle. Lambda approach (beta on mature ERP, full CRP) equals about +0.6% here | E27: 0
B28: Cost of equity year 1 (method per Beta_Evidence B41) | C28: % | E28: =$E$24+IF(Beta_Evidence!$B$41=2,$E$26*($E$25-Beta_Evidence!$B$17)+Beta_Evidence!$B$17,$E$26*$E$25)+$E$27 -> 0.11229724
B29: Weight on relative valuation in the 12m target price (rest = DDM = RI) | C29: % | D29: Team judgement: MSCI consultation on Standalone status (15 Oct 2026) is market-wide; peer multiples carry it. Sensitivity in Valuation_Checks section 4 | E29: 0.33333333
B30: Terminal growth (g) - Bear / Base / Bull | C30: % | E30: 0.04 | F30: 0.045 | G30: 0.05
B31: Terminal growth (g) (live) | C31: % | E31: =CHOOSE($E$3,$E$30,$F$30,$G$30) -> 0.045
B32: Scenario CoE adder - Bear / Base / Bull | C32: % | D32: Set to 0 in v4.0 (was +0.5% / 0 / -0.25%): scenarios now differ by operating drivers only, Ke is a single estimate | E32: 0 | F32: 0 | G32: 0
B33: Scenario CoE adder (live) | C33: % | E33: =CHOOSE($E$3,$E$32,$F$32,$G$32)+$E$14 -> 0
B34: Cost of equity year 1 (live); yearly path in row 378 | C34: % | E34: =$E$28+$E$33 -> 0.11229724
B35: Target CAR (internal floor) | C35: % | D35: Reported CAR 20.41% at Jun-26 (Q2-26 statement); mgmt aim to stay >20%; post-rights-issue 22-24% (prospectus) | E35: 0.2
B36: Regulatory minimum CAR incl. buffers | C36: % | D36: AR2025: KPMM per risk profile 9.99% + capital conservation buffer 2.5% + D-SIB 1.0%; countercyclical 0% | E36: 0.1349
B37: FDR cap | C37: % | E37: 0.92
B38: Min cash & BI placements / DPK (GWM proxy) | C38: % | D38: Sharia GWM 7.5% (conventional 9.0%) | E38: 0.075
B39: Terminal ROE spread over Ke - Bear / Base / Bull | C39: % | D39: Terminal ROE = Ke + spread. Evidence and anchors in sheet Terminal_ROE | E39: 0 | F39: 0.02 | G39: 0.04
B40: 1b. Macro (scenario) | E40: FY21A | F40: FY22A | G40: FY23A | H40: FY24A | I40: FY25A | J40: FY26E | K40: FY27E | L40: FY28E | M40: FY29E | N40: FY30E | O40: FY31E | P40: FY32E | Q40: FY33E | R40: FY34E | S40: FY35E
B41: BI rate (year-end) - Bear | C41: % | J41: 0.0625 | K41: 0.0575 | L41: 0.055 | M41: 0.0525 | N41: 0.05 | O41: 0.05 | P41: 0.05 | Q41: 0.05 | R41: 0.05 | S41: 0.05
B42: BI rate (year-end) - Base | C42: % | J42: 0.0575 | K42: 0.0525 | L42: 0.0475 | M42: 0.045 | N42: 0.045 | O42: 0.045 | P42: 0.045 | Q42: 0.045 | R42: 0.045 | S42: 0.045
...

Sheet Valuation_Checks
A1: Valuation cross-checks
A2: Cross-check methods only; the target price comes from Sheet1 (DDM = residual income). Peer multiples and their implied prices sit in Sheet1 section 5.
A4: 1. Banking FCFE (excess capital over the target CAR is distributable) | B4: Dec-25 | C4: Valuation date | D4: 12m PT
A5: Banking FCFE value per share (Rp) | B5: =(SUMPRODUCT(Sheet1!J416:S416,Sheet1!J377:S377)+Sheet1!E383*Sheet1!E382*Sheet1!S175/(Sheet1!S378-Sheet1!E31)*Sheet1!S377)/Sheet1!E21*1000 -> 2356.9226 | C5: =B5*(1+Sheet1!E34)^Sheet1!E399-Sheet1!E400 -> 2526.1039 | D5: =C5*(1+Sheet1!E34)-Sheet1!E401 -> 2769.6155 | H5: FCFE = NI + OCI - target CAR x change in RWA (Sheet1 row 416). Above DDM because the target CAR (Sheet1 E35) is below the forecast CAR.
A7: 2. Price-to-book cross-checks | B7: Value / share (Rp) | C7: Multiple
A8: Justified P/B on FY26E BVPS = (average ROE FY26E-35E - g)/(Ke - g) | B8: =C8*Sheet1!J351 -> 1736.88 | C8: =(AVERAGE(Sheet1!J347:S347)-Sheet1!E31)/(Sheet1!S378-Sheet1!E31) -> 1.3611977
A9: Exit P/B at peer median (MRQ) on FY35E BVPS, plus PV of dividends FY26E-35E | B9: =SUM(Sheet1!J381:S381)+C9*Sheet1!S351*Sheet1!S377 -> 1562.6414 | C9: =Sheet1!G466 -> 1.1117615 | H9: Exit multiple = peer median P/B on Jun-26 book (Sheet1 G466), not a judgement input.
A10: Average of the two P/B checks | B10: =AVERAGE(B8:B9) -> 1649.7607
A12: 3. Sensitivity: value per share at Dec-25 (Rp), flat Ke (around the stable Ke) down, terminal growth across; spread = live | B12: 3.5% | C12: 4.0% | D12: 4.5% | E12: 5.0% | F12: 5.5%
A13: Terminal growth | B13: 0.035 | C13: 0.04 | D13: 0.045 | E13: 0.05 | F13: 0.055
A14: =Sheet1!$S$378+(-0.02) -> 0.1025 | B14: =(Sheet1!$I$175+SUMPRODUCT((Sheet1!$J$154:$S$154-$A14*Sheet1!$I$175:$R$175)/(1+$A14)^Sheet1!$J$376:$S$376)+Sheet1!$S$175*(Sheet1!$E$382-Sheet1!$S$378)/($A14-B$13)/(1+$A14)^10)/Sheet1!$E$21*1000 -> 2191.4118 | C14: =(Sheet1!$I$175+SUMPRODUCT((Sheet1!$J$154:$S$154-$A14*Sheet1!$I$175:$R$175)/(1+$A14)^Sheet1!$J$376:$S$376)+Sheet1!$S$175*(Sheet1!$E$382-Sheet1!$S$378)/($A14-C$13)/(1+$A14)^10)/Sheet1!$E$21*1000 -> 2222.1614 | D14: =(Sheet1!$I$175+SUMPRODUCT((Sheet1!$J$154:$S$154-$A14*Sheet1!$I$175:$R$175)/(1+$A14)^Sheet1!$J$376:$S$376)+Sheet1!$S$175*(Sheet1!$E$382-Sheet1!$S$378)/($A14-D$13)/(1+$A14)^10)/Sheet1!$E$21*1000 -> 2258.2587 | E14: =(Sheet1!$I$175+SUMPRODUCT((Sheet1!$J$154:$S$154-$A14*Sheet1!$I$175:$R$175)/(1+$A14)^Sheet1!$J$376:$S$376)+Sheet1!$S$175*(Sheet1!$E$382-Sheet1!$S$378)/($A14-E$13)/(1+$A14)^10)/Sheet1!$E$21*1000 -> 2301.2318 | F14: =(Sheet1!$I$175+SUMPRODUCT((Sheet1!$J$154:$S$154-$A14*Sheet1!$I$175:$R$175)/(1+$A14)^Sheet1!$J$376:$S$376)+Sheet1!$S$175*(Sheet1!$E$382-Sheet1!$S$378)/($A14-F$13)/(1+$A14)^10)/Sheet1!$E$21*1000 -> 2353.2517 | H14: Row 3 is the live Ke; column 3 is the Base spread. Terminal growth = Sheet1 E31.
A15: =Sheet1!$S$378+(-0.01) -> 0.1125 | B15: =(Sheet1!$I$175+SUMPRODUCT((Sheet1!$J$154:$S$154-$A15*Sheet1!$I$175:$R$175)/(1+$A15)^Sheet1!$J$376:$S$376)+Sheet1!$S$175*(Sheet1!$E$382-Sheet1!$S$378)/($A15-B$13)/(1+$A15)^10)/Sheet1!$E$21*1000 -> 1966.8415 | C15: =(Sheet1!$I$175+SUMPRODUCT((Sheet1!$J$154:$S$154-$A15*Sheet1!$I$175:$R$175)/(1+$A15)^Sheet1!$J$376:$S$376)+Sheet1!$S$175*(Sheet1!$E$382-Sheet1!$S$378)/($A15-C$13)/(1+$A15)^10)/Sheet1!$E$21*1000 -> 1987.936 | D15: =(Sheet1!$I$175+SUMPRODUCT((Sheet1!$J$154:$S$154-$A15*Sheet1!$I$175:$R$175)/(1+$A15)^Sheet1!$J$376:$S$376)+Sheet1!$S$175*(Sheet1!$E$382-Sheet1!$S$378)/($A15-D$13)/(1+$A15)^10)/Sheet1!$E$21*1000 -> 2012.1556 | E15: =(Sheet1!$I$175+SUMPRODUCT((Sheet1!$J$154:$S$154-$A15*Sheet1!$I$175:$R$175)/(1+$A15)^Sheet1!$J$376:$S$376)+Sheet1!$S$175*(Sheet1!$E$382-Sheet1!$S$378)/($A15-E$13)/(1+$A15)^10)/Sheet1!$E$21*1000 -> 2040.2504 | F15: =(Sheet1!$I$175+SUMPRODUCT((Sheet1!$J$154:$S$154-$A15*Sheet1!$I$175:$R$175)/(1+$A15)^Sheet1!$J$376:$S$376)+Sheet1!$S$175*(Sheet1!$E$382-Sheet1!$S$378)/($A15-F$13)/(1+$A15)^10)/Sheet1!$E$21*1000 -> 2073.2312
A16: =Sheet1!$S$378+(0) -> 0.1225 | B16: =(Sheet1!$I$175+SUMPRODUCT((Sheet1!$J$154:$S$154-$A16*Sheet1!$I$175:$R$175)/(1+$A16)^Sheet1!$J$376:$S$376)+Sheet1!$S$175*(Sheet1!$E$382-Sheet1!$S$378)/($A16-B$13)/(1+$A16)^10)/Sheet1!$E$21*1000 -> 1775.8334 | C16: =(Sheet1!$I$175+SUMPRODUCT((Sheet1!$J$154:$S$154-$A16*Sheet1!$I$175:$R$175)/(1+$A16)^Sheet1!$J$376:$S$376)+Sheet1!$S$175*(Sheet1!$E$382-Sheet1!$S$378)/($A16-C$13)/(1+$A16)^10)/Sheet1!$E$21*1000 -> 1790.847 | D16: =(Sheet1!$I$175+SUMPRODUCT((Sheet1!$J$154:$S$154-$A16*Sheet1!$I$175:$R$175)/(1+$A16)^Sheet1!$J$376:$S$376)+Sheet1!$S$175*(Sheet1!$E$382-Sheet1!$S$378)/($A16-D$13)/(1+$A16)^10)/Sheet1!$E$21*1000 -> 1807.7978 | E16: =(Sheet1!$I$175+SUMPRODUCT((Sheet1!$J$154:$S$154-$A16*Sheet1!$I$175:$R$175)/(1+$A16)^Sheet1!$J$376:$S$376)+Sheet1!$S$175*(Sheet1!$E$382-Sheet1!$S$378)/($A16-E$13)/(1+$A16)^10)/Sheet1!$E$21*1000 -> 1827.0866 | F16: =(Sheet1!$I$175+SUMPRODUCT((Sheet1!$J$154:$S$154-$A16*Sheet1!$I$175:$R$175)/(1+$A16)^Sheet1!$J$376:$S$376)+Sheet1!$S$175*(Sheet1!$E$382-Sheet1!$S$378)/($A16-F$13)/(1+$A16)^10)/Sheet1!$E$21*1000 -> 1849.233
A17: =Sheet1!$S$378+(0.01) -> 0.1325 | B17: =(Sheet1!$I$175+SUMPRODUCT((Sheet1!$J$154:$S$154-$A17*Sheet1!$I$175:$R$175)/(1+$A17)^Sheet1!$J$376:$S$376)+Sheet1!$S$175*(Sheet1!$E$382-Sheet1!$S$378)/($A17-B$13)/(1+$A17)^10)/Sheet1!$E$21*1000 -> 1610.595 | C17: =(Sheet1!$I$175+SUMPRODUCT((Sheet1!$J$154:$S$154-$A17*Sheet1!$I$175:$R$175)/(1+$A17)^Sheet1!$J$376:$S$376)+Sheet1!$S$175*(Sheet1!$E$382-Sheet1!$S$378)/($A17-C$13)/(1+$A17)^10)/Sheet1!$E$21*1000 -> 1621.5921 | D17: =(Sheet1!$I$175+SUMPRODUCT((Sheet1!$J$154:$S$154-$A17*Sheet1!$I$175:$R$175)/(1+$A17)^Sheet1!$J$376:$S$376)+Sheet1!$S$175*(Sheet1!$E$382-Sheet1!$S$378)/($A17-D$13)/(1+$A17)^10)/Sheet1!$E$21*1000 -> 1633.8461 | E17: =(Sheet1!$I$175+SUMPRODUCT((Sheet1!$J$154:$S$154-$A17*Sheet1!$I$175:$R$175)/(1+$A17)^Sheet1!$J$376:$S$376)+Sheet1!$S$175*(Sheet1!$E$382-Sheet1!$S$378)/($A17-E$13)/(1+$A17)^10)/Sheet1!$E$21*1000 -> 1647.5854 | F17: =(Sheet1!$I$175+SUMPRODUCT((Sheet1!$J$154:$S$154-$A17*Sheet1!$I$175:$R$175)/(1+$A17)^Sheet1!$J$376:$S$376)+Sheet1!$S$175*(Sheet1!$E$382-Sheet1!$S$378)/($A17-F$13)/(1+$A17)^10)/Sheet1!$E$21*1000 -> 1663.0975
A18: =Sheet1!$S$378+(0.02) -> 0.1425 | B18: =(Sheet1!$I$175+SUMPRODUCT((Sheet1!$J$154:$S$154-$A18*Sheet1!$I$175:$R$175)/(1+$A18)^Sheet1!$J$376:$S$376)+Sheet1!$S$175*(Sheet1!$E$382-Sheet1!$S$378)/($A18-B$13)/(1+$A18)^10)/Sheet1!$E$21*1000 -> 1465.9083 | C18: =(Sheet1!$I$175+SUMPRODUCT((Sheet1!$J$154:$S$154-$A18*Sheet1!$I$175:$R$175)/(1+$A18)^Sheet1!$J$376:$S$376)+Sheet1!$S$175*(Sheet1!$E$382-Sheet1!$S$378)/($A18-C$13)/(1+$A18)^10)/Sheet1!$E$21*1000 -> 1474.1518 | D18: =(Sheet1!$I$175+SUMPRODUCT((Sheet1!$J$154:$S$154-$A18*Sheet1!$I$175:$R$175)/(1+$A18)^Sheet1!$J$376:$S$376)+Sheet1!$S$175*(Sheet1!$E$382-Sheet1!$S$378)/($A18-D$13)/(1+$A18)^10)/Sheet1!$E$21*1000 -> 1483.2409 | E18: =(Sheet1!$I$175+SUMPRODUCT((Sheet1!$J$154:$S$154-$A18*Sheet1!$I$175:$R$175)/(1+$A18)^Sheet1!$J$376:$S$376)+Sheet1!$S$175*(Sheet1!$E$382-Sheet1!$S$378)/($A18-E$13)/(1+$A18)^10)/Sheet1!$E$21*1000 -> 1493.3125 | F18: =(Sheet1!$I$175+SUMPRODUCT((Sheet1!$J$154:$S$154-$A18*Sheet1!$I$175:$R$175)/(1+$A18)^Sheet1!$J$376:$S$376)+Sheet1!$S$175*(Sheet1!$E$382-Sheet1!$S$378)/($A18-F$13)/(1+$A18)^10)/Sheet1!$E$21*1000 -> 1504.5352
A19: Flat Ke at the stable level; the model uses a rising path from the year-1 Ke, so no cell equals Sheet1 E387.
A21: 4. Weight on relative valuation: value today and 12m target (Rp per share) | B21: Today | C21: 12m target
A22: 0 | B22: =(1-A22)*Sheet1!$E$402+A22*Sheet1!$E$411 -> 2019.8393 | C22: =(1-A22)*AVERAGE(Sheet1!$E$404,Sheet1!$E$405)+A22*(Sheet1!$E$411*(1+Sheet1!$E$34)-Sheet1!$E$401) -> 2206.4988 | H22: Row = weight on relative valuation (Sheet1 E29). Relative value today = Sheet1 E411; 12m = rolled at Ke less the next dividend.
A23: 0.2 | B23: =(1-A23)*Sheet1!$E$402+A23*Sheet1!$E$411 -> 1844.3247 | C23: =(1-A23)*AVERAGE(Sheet1!$E$404,Sheet1!$E$405)+A23*(Sheet1!$E$411*(1+Sheet1!$E$34)-Sheet1!$E$401) -> 2011.2744
A24: 0.25 | B24: =(1-A24)*Sheet1!$E$402+A24*Sheet1!$E$411 -> 1800.446 | C24: =(1-A24)*AVERAGE(Sheet1!$E$404,Sheet1!$E$405)+A24*(Sheet1!$E$411*(1+Sheet1!$E$34)-Sheet1!$E$401) -> 1962.4683
A25: 0.33333333 | B25: =(1-A25)*Sheet1!$E$402+A25*Sheet1!$E$411 -> 1727.315 | C25: =(1-A25)*AVERAGE(Sheet1!$E$404,Sheet1!$E$405)+A25*(Sheet1!$E$411*(1+Sheet1!$E$34)-Sheet1!$E$401) -> 1881.1248
A26: 0.4 | B26: =(1-A26)*Sheet1!$E$402+A26*Sheet1!$E$411 -> 1668.8101 | C26: =(1-A26)*AVERAGE(Sheet1!$E$404,Sheet1!$E$405)+A26*(Sheet1!$E$411*(1+Sheet1!$E$34)-Sheet1!$E$401) -> 1816.05
A27: 0.5 | B27: =(1-A27)*Sheet1!$E$402+A27*Sheet1!$E$411 -> 1581.0528 | C27: =(1-A27)*AVERAGE(Sheet1!$E$404,Sheet1!$E$405)+A27*(Sheet1!$E$411*(1+Sheet1!$E$34)-Sheet1!$E$401) -> 1718.4378

Sheet Charts
B1: Charts (data blocks sit above each chart; schedules read from Sheet1)
B2: Chart 1 - Operating income bridge FY25A to FY35E (Rp bn)
E3: Value | F3: Base (hidden) | G3: Increase | H3: Decrease | I3: Total | J3: Cumulative
B4: FY25A operating income | E4: =Sheet1!$I$145 -> 26065.682 | F4: 0 | G4: 0 | H4: 0 | I4: =E4 -> 26065.682 | J4: =E4 -> 26065.682
B5: Financing volume | E5: =(Sheet1!$S$214-Sheet1!$I$214)*Sheet1!$I$235 -> 46413.355 | F5: =MIN(J4,J4+E5) -> 26065.682 | G5: =MAX(E5,0) -> 46413.355 | H5: =MAX(-E5,0) -> 0 | I5: 0 | J5: =J4+E5 -> 72479.037
B6: Gross yield | E6: =(Sheet1!$S$235-Sheet1!$I$235)*Sheet1!$S$214 -> -7397.6373 | F6: =MIN(J5,J5+E6) -> 65081.4 | G6: =MAX(E6,0) -> 0 | H6: =MAX(-E6,0) -> 7397.6373 | I6: 0 | J6: =J5+E6 -> 65081.4
B7: Funding cost | E7: =-(Sheet1!$S$142-Sheet1!$I$142) -> -6558.6895 | F7: =MIN(J6,J6+E7) -> 58522.71 | G7: =MAX(E7,0) -> 0 | H7: =MAX(-E7,0) -> 6558.6895 | I7: 0 | J7: =J6+E7 -> 58522.71
B8: Fee income | E8: =Sheet1!$S$144-Sheet1!$I$144 -> 13100.149 | F8: =MIN(J7,J7+E8) -> 58522.71 | G8: =MAX(E8,0) -> 13100.149 | H8: =MAX(-E8,0) -> 0 | I8: 0 | J8: =J7+E8 -> 71622.859
B9: Rights-issue capital deployed | E9: =Sheet1!$S$326 -> 575.28 | F9: =MIN(J8,J8+E9) -> 71622.859 | G9: =MAX(E9,0) -> 575.28 | H9: =MAX(-E9,0) -> 0 | I9: 0 | J9: =J8+E9 -> 72198.139
B10: FY35E operating income | E10: =Sheet1!$S$145 -> 72198.139 | F10: 0 | G10: 0 | H10: 0 | I10: =E10 -> 72198.139 | J10: =E10 -> 72198.139
B11: Check: cumulative before end total = end total | E11: =J9-E10 -> 0
B33: Chart 2 - Net margin income bridge FY25A to FY35E (Rp bn)
E34: Value | F34: Base (hidden) | G34: Increase | H34: Decrease | I34: Total | J34: Cumulative
B35: FY25A NMI | E35: =Sheet1!$I$143 -> 19129.086 | F35: 0 | G35: 0 | H35: 0 | I35: =E35 -> 19129.086 | J35: =E35 -> 19129.086
B36: Earning-asset volume | E36: =(Sheet1!$S$214-Sheet1!$I$214)*Sheet1!$I$235 -> 46413.355 | F36: =MIN(J35,J35+E36) -> 19129.086 | G36: =MAX(E36,0) -> 46413.355 | H36: =MAX(-E36,0) -> 0 | I36: 0 | J36: =J35+E36 -> 65542.441
B37: Gross yield | E37: =(Sheet1!$S$235-Sheet1!$I$235)*Sheet1!$S$214 -> -7397.6373 | F37: =MIN(J36,J36+E37) -> 58144.804 | G37: =MAX(E37,0) -> 0 | H37: =MAX(-E37,0) -> 7397.6373 | I37: 0 | J37: =J36+E37 -> 58144.804
B38: Funding volume | E38: =-(AVERAGE(Sheet1!$S$222,Sheet1!$R$222)-AVERAGE(Sheet1!$I$222,Sheet1!$H$222))*Sheet1!$I$229 -> -14274.034 | F38: =MIN(J37,J37+E38) -> 43870.77 | G38: =MAX(E38,0) -> 0 | H38: =MAX(-E38,0) -> 14274.034 | I38: 0 | J38: =J37+E38 -> 43870.77
B39: Funding rate | E39: =-(Sheet1!$S$229-Sheet1!$I$229)*AVERAGE(Sheet1!$S$222,Sheet1!$R$222) -> 7715.3443 | F39: =MIN(J38,J38+E39) -> 43870.77 | G39: =MAX(E39,0) -> 7715.3443 | H39: =MAX(-E39,0) -> 0 | I39: 0 | J39: =J38+E39 -> 51586.114
B40: Rights-issue capital deployed | E40: =Sheet1!$S$326 -> 575.28 | F40: =MIN(J39,J39+E40) -> 51586.114 | G40: =MAX(E40,0) -> 575.28 | H40: =MAX(-E40,0) -> 0 | I40: 0 | J40: =J39+E40 -> 52161.394
B41: FY35E NMI | E41: =Sheet1!$S$143 -> 52161.394 | F41: 0 | G41: 0 | H41: 0 | I41: =E41 -> 52161.394 | J41: =E41 -> 52161.394
B42: Check: cumulative before end total = end total | E42: =J40-E41 -> 0
B64: Chart 3 - Revenue-to-net-profit walk FY35E (Rp bn)
E65: Value | F65: Base (hidden) | G65: Increase | H65: Decrease | I65: Total | J65: Cumulative
B66: Gross margin income | E66: =Sheet1!$S$141 -> 67856.489 | F66: 0 | G66: 0 | H66: 0 | I66: =E66 -> 67856.489 | J66: =E66 -> 67856.489
B67: Profit-sharing expense | E67: =-Sheet1!$S$142 -> -15695.095 | F67: =MIN(J66,J66+E67) -> 52161.394 | G67: =MAX(E67,0) -> 0 | H67: =MAX(-E67,0) -> 15695.095 | I67: 0 | J67: =J66+E67 -> 52161.394
B68: Fee income | E68: =Sheet1!$S$144 -> 20036.745 | F68: =MIN(J67,J67+E68) -> 52161.394 | G68: =MAX(E68,0) -> 20036.745 | H68: =MAX(-E68,0) -> 0 | I68: 0 | J68: =J67+E68 -> 72198.139
B69: Overhead | E69: =-Sheet1!$S$149 -> -36460.06 | F69: =MIN(J68,J68+E69) -> 35738.079 | G69: =MAX(E69,0) -> 0 | H69: =MAX(-E69,0) -> 36460.06 | I69: 0 | J69: =J68+E69 -> 35738.079
B70: Provisions | E70: =-Sheet1!$S$151 -> -5918.1099 | F70: =MIN(J69,J69+E70) -> 29819.969 | G70: =MAX(E70,0) -> 0 | H70: =MAX(-E70,0) -> 5918.1099 | I70: 0 | J70: =J69+E70 -> 29819.969
B71: Tax & other | E71: =-Sheet1!$S$153 -> -7329.1398 | F71: =MIN(J70,J70+E71) -> 22490.829 | G71: =MAX(E71,0) -> 0 | H71: =MAX(-E71,0) -> 7329.1398 | I71: 0 | J71: =J70+E71 -> 22490.829
B72: Net profit FY35E | E72: =Sheet1!$S$154 -> 22490.829 | F72: 0 | G72: 0 | H72: 0 | I72: =E72 -> 22490.829 | J72: =E72 -> 22490.829
B73: Check: cumulative before end total = end total | E73: =J71-E72 -> 0
B95: Chart 7 - ROE walk FY25A to FY35E (% of avg equity)
E96: Value | F96: Base (hidden) | G96: Increase | H96: Decrease | I96: Total | J96: Cumulative
B97: FY25A ROE | E97: =Sheet1!$I$359 -> 0.15604034 | F97: 0 | G97: 0 | H97: 0 | I97: =E97 -> 0.15604034 | J97: =E97 -> 0.15604034
B98: NMI / equity | E98: =Sheet1!$S$354-Sheet1!$I$354 -> -0.05537199 | F98: =MIN(J97,J97+E98) -> 0.10066835 | G98: =MAX(E98,0) -> 0 | H98: =MAX(-E98,0) -> 0.05537199 | I98: 0 | J98: =J97+E98 -> 0.10066835
B99: Fees / equity | E99: =Sheet1!$S$355-Sheet1!$I$355 -> -0.012785922 | F99: =MIN(J98,J98+E99) -> 0.087882424 | G99: =MAX(E99,0) -> 0 | H99: =MAX(-E99,0) -> 0.012785922 | I99: 0 | J99: =J98+E99 -> 0.087882424
B100: Overhead / equity | E100: =Sheet1!$S$356-Sheet1!$I$356 -> 0.045503774 | F100: =MIN(J99,J99+E100) -> 0.087882424 | G100: =MAX(E100,0) -> 0.045503774 | H100: =MAX(-E100,0) -> 0 | I100: 0 | J100: =J99+E100 -> 0.1333862
B101: Provisions / equity | E101: =Sheet1!$S$357-Sheet1!$I$357 -> 0.010130218 | F101: =MIN(J100,J100+E101) -> 0.1333862 | G101: =MAX(E101,0) -> 0.010130218 | H101: =MAX(-E101,0) -> 0 | I101: 0 | J101: =J100+E101 -> 0.14351642
B102: Tax / equity | E102: =Sheet1!$S$358-Sheet1!$I$358 -> 0.0026807337 | F102: =MIN(J101,J101+E102) -> 0.14351642 | G102: =MAX(E102,0) -> 0.0026807337 | H102: =MAX(-E102,0) -> 0 | I102: 0 | J102: =J101+E102 -> 0.14619715
B103: FY35E ROE | E103: =Sheet1!$S$359 -> 0.14619715 | F103: 0 | G103: 0 | H103: 0 | I103: =E103 -> 0.14619715 | J103: =E103 -> 0.14619715
...

Sheet Terminal_ROE
A1: Terminal ROE: evidence, choice and sensitivity
A2: Rule: terminal ROE = stable cost of equity (Sheet1 S378, beta 1.0) + spread (Sheet1 row 39). Country risk therefore raises Ke and terminal ROE together, and the same terminal ROE drives the DDM (payout 1 - g/ROE) and the residual income terminal value, so both give the same value.
A4: 1. Evidence (live links) | B4: ROE | C4: Spread vs Ke
A6: Stable cost of equity (FY35E, floor: no excess return) | B6: =Sheet1!S378 -> 0.1225 | C6: =B6-$B$6 -> 0 | H6: Damodaran limiting case for stable growth: excess returns competed away
A7: Market-implied sustainable ROE at current price | B7: =Sheet1!E414 -> 0.12034991 | C7: =B7-$B$6 -> -0.002150091 | H7: PB x (Ke - g) + g at the current price
A8: BBNI ROE, 1H26 annualised (lowest-ROE KBMI 4 state bank) | B8: =Sheet1!J461 -> 0.1299486 | C8: =B8-$B$6 -> 0.0074486015 | H8: BBNI 1H26 statements
A9: BRIS ROE, 1H26 annualised | B9: =Sheet1!J464 -> 0.16139695 | C9: =B9-$B$6 -> 0.03889695 | H9: 1H26 interim statement
A10: BRIS highest annual ROE FY22A-FY25A | B10: =MAX(Sheet1!F347:I347) -> 0.1672435 | C10: =B10-$B$6 -> 0.044743496 | H10: Annual reports
A11: Midpoint of Ke and model FY35E ROE | B11: =AVERAGE(B6,B14) -> 0.13434857 | C11: =B11-$B$6 -> 0.011848575 | H11: Half of the FY35E excess return survives in perpetuity
A12: Peer median ROE, 1H26 annualised (5 banks incl. BTPS) | B12: =Sheet1!J466 -> 0.1871695 | C12: =B12-$B$6 -> 0.064669505 | H12: Includes BBCA and BMRI, which have structural franchise advantages
A13: BRIS lowest annual ROE FY22A-FY25A | B13: =MIN(Sheet1!F347:I347) -> 0.14559142 | C13: =B13-$B$6 -> 0.023091415 | H13: Annual reports
A14: Model FY35E ROE (end of explicit forecast) | B14: =Sheet1!S347 -> 0.14619715 | C14: =B14-$B$6 -> 0.02369715 | H14: Output of the operating drivers
A15: BRIS average ROE FY22A-FY25A | B15: =AVERAGE(Sheet1!F347:I347) -> 0.15669375 | C15: =B15-$B$6 -> 0.034193748 | H15: Annual reports
A17: 2. Choice by scenario | B17: Bear | C17: Base | D17: Bull
A18: Spread over Ke (input, Sheet1 row 39) | B18: =Sheet1!E39 -> 0 | C18: =Sheet1!F39 -> 0.02 | D18: =Sheet1!G39 -> 0.04
A19: Terminal ROE at live Ke | B19: =$B$6+B18 -> 0.1225 | C19: =$B$6+C18 -> 0.1425 | D19: =$B$6+D18 -> 0.1625
A20: Implied terminal P/B = (ROE - g)/(Ke - g), Base g | B20: =(B19-Sheet1!$F$30)/($B$6-Sheet1!$F$30) -> 1 | C20: =(C19-Sheet1!$F$30)/($B$6-Sheet1!$F$30) -> 1.2580645 | D20: =(D19-Sheet1!$F$30)/($B$6-Sheet1!$F$30) -> 1.516129
A21: Sustainable terminal payout = 1 - g/ROE, Base g | B21: =1-Sheet1!$F$30/B19 -> 0.63265306 | C21: =1-Sheet1!$F$30/C19 -> 0.68421053 | D21: =1-Sheet1!$F$30/D19 -> 0.72307692
A23: Why these spreads
A24: Bear, +0pp (= stable Ke, about 12.3%): no excess return in perpetuity (Damodaran limiting case); close to the market-implied sustainable ROE at the current price (row 7) and to BBNI ROE TTM (row 8).
A25: Base, +2.0pp (about 14.3%): just below BRIS's lowest annual ROE of FY22A-FY25A (row 13) and the model FY35E ROE (row 14), so the case assumes modest erosion of today's returns; implied terminal P/B about 1.3x sits between the peer median of about 1.2x (Sheet1 G466) and BRIS's FY22-FY25 year-end range of 1.8x-2.9x; sustainable payout about 68% is close to the FY35E policy payout of 65% (Sheet1 S106).
A26: Bull, +4.0pp (about 16.3%): BRIS keeps the returns it earned in FY22A-FY25A (average row 15, highest row 10).
A27: Peer ROEs: 1H26 interim statements and presentations, profit annualised. BRIS from its 1H26 interim statement.
A29: 3. Sensitivity of intrinsic value (DDM = RI) to the spread; target-price blend excluded | B29: Spread | C29: Terminal ROE | D29: Terminal P/B | E29: Value Dec-25 (Rp) | F29: 12m PT (Rp) | G29: Upside
B30: 0 | C30: =(Sheet1!$S$378+B30) -> 0.1225 | D30: =((Sheet1!$S$378+B30)-Sheet1!$E$31)/(Sheet1!$S$378-Sheet1!$E$31) -> 1 | E30: =(Sheet1!$I$175+SUM(Sheet1!$J$392:$S$392)+Sheet1!$S$175*B30/(Sheet1!$S$378-Sheet1!$E$31)*Sheet1!$S$377)/Sheet1!$E$21*1000 -> 1597.8858 | F30: =(E30*(1+Sheet1!$E$34)^Sheet1!$E$399-Sheet1!$E$400)*(1+Sheet1!$E$34)-Sheet1!$E$401 -> 1852.9856 | G30: =F30/Sheet1!$E$20-1 -> 0.69222429
B31: 0.01 | C31: =(Sheet1!$S$378+B31) -> 0.1325 | D31: =((Sheet1!$S$378+B31)-Sheet1!$E$31)/(Sheet1!$S$378-Sheet1!$E$31) -> 1.1290323 | E31: =(Sheet1!$I$175+SUM(Sheet1!$J$392:$S$392)+Sheet1!$S$175*B31/(Sheet1!$S$378-Sheet1!$E$31)*Sheet1!$S$377)/Sheet1!$E$21*1000 -> 1744.2533 | F31: =(E31*(1+Sheet1!$E$34)^Sheet1!$E$399-Sheet1!$E$400)*(1+Sheet1!$E$34)-Sheet1!$E$401 -> 2029.7422 | G31: =F31/Sheet1!$E$20-1 -> 0.85364585
B32: 0.02 | C32: =(Sheet1!$S$378+B32) -> 0.1425 | D32: =((Sheet1!$S$378+B32)-Sheet1!$E$31)/(Sheet1!$S$378-Sheet1!$E$31) -> 1.2580645 | E32: =(Sheet1!$I$175+SUM(Sheet1!$J$392:$S$392)+Sheet1!$S$175*B32/(Sheet1!$S$378-Sheet1!$E$31)*Sheet1!$S$377)/Sheet1!$E$21*1000 -> 1890.6207 | F32: =(E32*(1+Sheet1!$E$34)^Sheet1!$E$399-Sheet1!$E$400)*(1+Sheet1!$E$34)-Sheet1!$E$401 -> 2206.4988 | G32: =F32/Sheet1!$E$20-1 -> 1.0150674
B33: 0.03 | C33: =(Sheet1!$S$378+B33) -> 0.1525 | D33: =((Sheet1!$S$378+B33)-Sheet1!$E$31)/(Sheet1!$S$378-Sheet1!$E$31) -> 1.3870968 | E33: =(Sheet1!$I$175+SUM(Sheet1!$J$392:$S$392)+Sheet1!$S$175*B33/(Sheet1!$S$378-Sheet1!$E$31)*Sheet1!$S$377)/Sheet1!$E$21*1000 -> 2036.9881 | F33: =(E33*(1+Sheet1!$E$34)^Sheet1!$E$399-Sheet1!$E$400)*(1+Sheet1!$E$34)-Sheet1!$E$401 -> 2383.2554 | G33: =F33/Sheet1!$E$20-1 -> 1.176489
B34: 0.04 | C34: =(Sheet1!$S$378+B34) -> 0.1625 | D34: =((Sheet1!$S$378+B34)-Sheet1!$E$31)/(Sheet1!$S$378-Sheet1!$E$31) -> 1.516129 | E34: =(Sheet1!$I$175+SUM(Sheet1!$J$392:$S$392)+Sheet1!$S$175*B34/(Sheet1!$S$378-Sheet1!$E$31)*Sheet1!$S$377)/Sheet1!$E$21*1000 -> 2183.3556 | F34: =(E34*(1+Sheet1!$E$34)^Sheet1!$E$399-Sheet1!$E$400)*(1+Sheet1!$E$34)-Sheet1!$E$401 -> 2560.012 | G34: =F34/Sheet1!$E$20-1 -> 1.3379105
B35: 0.05 | C35: =(Sheet1!$S$378+B35) -> 0.1725 | D35: =((Sheet1!$S$378+B35)-Sheet1!$E$31)/(Sheet1!$S$378-Sheet1!$E$31) -> 1.6451613 | E35: =(Sheet1!$I$175+SUM(Sheet1!$J$392:$S$392)+Sheet1!$S$175*B35/(Sheet1!$S$378-Sheet1!$E$31)*Sheet1!$S$377)/Sheet1!$E$21*1000 -> 2329.723 | F35: =(E35*(1+Sheet1!$E$34)^Sheet1!$E$399-Sheet1!$E$400)*(1+Sheet1!$E$34)-Sheet1!$E$401 -> 2736.7687 | G35: =F35/Sheet1!$E$20-1 -> 1.4993321
A36: Check: table at live spread equals Sheet1 intrinsic 12m value (must be 0) | B36: =ROUND(((Sheet1!$I$175+SUM(Sheet1!$J$392:$S$392)+Sheet1!$S$175*(Sheet1!$E$382-Sheet1!$S$378)/(Sheet1!$S$378-Sheet1!$E$31)*Sheet1!$S$377)/Sheet1!$E$21*1000*(1+Sheet1!$E$34)^Sheet1!$E$399-Sheet1!$E$400)*(1+Sheet1!$E$34)-Sheet1!$E$401-AVERAGE(Sheet1!$E$404,Sheet1!$E$405),6) -> 0

Sheet Beta_Evidence
A1: Beta evidence and cost of equity
A3: Observed betas (inputs, blue) | B3: Beta | C3: Source
A4: BRIS regression beta, 1Y | B4: 0.64 | C4: TradingView IDX:BRIS 1Y (checked by user 7-Oct-26). Alip labels this raw 0.64 as "2y weekly vs IHSG" (Bloomberg?): source and period to be confirmed
A5: BRIS regression beta, 5Y | B5: 0.13 | C5: TradingView IDX:BRIS (user-supplied). Not usable: very low explanatory power.
A6: BMRI regression beta, 5Y | B6: -0.05 | C6: TradingView (user-supplied). Shows IDX bank regressions vs IHSG are not informative.
A7: Damodaran Global Banks (Regional), 825 firms | B7: 0.51 | C7: Damodaran, Jan 2026, Betas by sector
A8: Damodaran Global Money Center, 604 firms | B8: 0.7 | C8: Damodaran, Jan 2026
A9: Damodaran US Money Center | B9: 0.76 | C9: Damodaran, Jan 2026
A10: Damodaran total market | B10: 1.04 | C10: Damodaran, Jan 2026
A11: BRIS regression beta, 60m monthly vs IHSG (own calc, sheet Beta) | B11: =Beta!B28 -> 0.69327187 | C11: Own regression from Investing.com monthly closes; standard error about 0.29, R-squared about 0.09: low precision
A12: Blume-adjusted selected raw beta = 0.67 x raw + 0.33 (feeds Sheet1 E26) | B12: =0.67*B39+0.33 -> 0.7588
A14: Cost of equity under two framings
A15: Risk-free (IDR), net of default spread | B15: =Sheet1!E24 -> 0.0556
A16: Total ERP incl. country risk (Indonesia) | B16: =Sheet1!E25 -> 0.0669
A17: Country risk premium (CRP) | B17: 0.0246 | C17: Damodaran Jan 2026, Indonesia (Baa2)
A18: Mature-market ERP = total ERP - CRP | B18: =B16-B17 -> 0.0423
A19: Beta used in model, year 1 (Sheet1!E26) | B19: =Sheet1!E26 -> 0.7588
A20: Ke year 1 (Sheet1!E28, method per B41) | B20: =Sheet1!E28 -> 0.11229724
A21: Ke (lambda, lambda=1): rf + CRP + beta x mature ERP, using BRIS 1Y raw | B21: =B15+B17+B4*B18 -> 0.107272
A22: Ke (lambda) using Blume-adjusted beta | B22: =B15+B17+B12*B18 -> 0.11229724
A23: Beta to enter in model to match lambda Ke (Blume) | B23: =(B22-B15)/B16 -> 0.84749238
A25: Sensitivity of the 12m blended target to the raw-beta choice (static runs; lambda method and beta convergence on)
A26: Raw beta choice (Beta_Evidence B38) | B26: Ke year 1 | C26: PT Bear | D26: PT Base | E26: PT Bull | F26: Prob-weighted PT | G26: Upside (prob-wtd)
A27: 1. TradingView 1Y raw 0.64 (default) | B27: 0.11229724 | C27: 1325.1816 | D27: 1881.1248 | E27: 2532.1125 | F27: =Prob_Justification!$B$25*C27+Prob_Justification!$B$26*D27+Prob_Justification!$B$27*E27 -> 1854.5971 | G27: =F27/Sheet1!$E$20-1 -> 0.69369602
A28: 2. Own 60m regression raw 0.69 | B28: 0.11380702 | C28: 1321.569 | D28: 1875.2219 | E28: 2523.4718 | F28: =Prob_Justification!$B$25*C28+Prob_Justification!$B$26*D28+Prob_Justification!$B$27*E28 -> 1848.7919 | G28: =F28/Sheet1!$E$20-1 -> 0.68839441
A29: 3. KSI broker raw 0.937 | B29: 0.12071452 | C29: 1305.3055 | D29: 1848.6233 | E29: 2484.5206 | F29: =Prob_Justification!$B$25*C29+Prob_Justification!$B$26*D29+Prob_Justification!$B$27*E29 -> 1822.6342 | G29: =F29/Sheet1!$E$20-1 -> 0.66450612
A30: 4. Manual raw 1.00 | B30: 0.1225 | C30: 1301.1714 | D30: 1841.8555 | E30: 2474.6055 | F30: =Prob_Justification!$B$25*C30+Prob_Justification!$B$26*D30+Prob_Justification!$B$27*E30 -> 1815.9789 | G30: =F30/Sheet1!$E$20-1 -> 0.6584282
A32: Static values from running the integrated workbook v11.2 on 17-Oct-26 (peers on 1H26 data). They do not update if inputs change. Ratings are not concluded here.
A33: Other observed estimates (not used in the model)
A34: Broker beta (KSI Equity Update, 10 Sep 2026, p.3) | B34: 0.937 | C34: Regression window and benchmark not disclosed
A35: TradingView 1Y beta, retrieved 17 Oct 2026 | B35: 0.63 | C35: Model keeps 0.64 (checked 7 Oct 2026); difference is within estimation error
A37: Beta and country-risk settings (feed Sheet1 cost of equity)
A38: Raw beta choice: 1 TradingView 1Y, 2 own 60m regression, 3 KSI broker, 4 manual | B38: 1 | C38: Default 1: model raw beta 0.64 (confirm source with Alip). With convergence on, the choice moves value about 3%.
A39: Selected raw beta | B39: =CHOOSE(B38,B4,B11,B34,B40) -> 0.64
A40: Manual raw beta | B40: 1
A41: Country risk premium: 1 = scaled by beta (Ke = rf + beta x total ERP), 2 = added in full (lambda = 1) | B41: 2 | C41: Default 2 (Damodaran lambda approach): a domestic bank carries the full country risk; scaling the 2.46% CRP by a 0.76 beta understates it. Relevant after MSCI consulted on reclassifying Indonesia to Standalone Market (15 Oct 2026).
A42: Beta converges to 1.0 by FY35E: 1 = yes, 0 = no | B42: 1 | C42: Default 1: Damodaran stable-growth convention, beta moves to 1.0 in the terminal period.

Sheet Prob_Justification
A1: Scenario probability justification
A2: Method: Base fixed by how much of FY26 is already known; the remaining probability is split Bear/Bull by the balance of dated evidence. Structured judgement, not a statistical estimate. Blue cells are inputs.
A4: Step 1. Base probability | C4: Why
A5: Probability of Base | B5: 0.5 | C5: 1H26 is reported (6 of 12 months of FY26). Base FY26 drivers sit on the 1H26 run-rate and inside management 2026 targets (financing +10-14%, cost of credit <0.84%, NIM >5.50%). Outcomes beyond FY26 are open, so no more than half.
A7: Step 2. Evidence tally (1 = point to that side) | B7: Weight | C7: Evidence (source) | D7: Direction
A8: HBH growth only +2.0% in 1H26 | B8: 1 | C8: Net funding income lagging asset growth, margin pressure (Q2 interim statement) | D8: Down
A9: Opex +17.5% vs revenue +10.5% | B9: 1 | C9: Cost growth above revenue; 2H25 CIR was 55.4% vs 52.6% in 1H26 (interim statements, AR2025) | D9: Down
A10: Q2 net income -11% QoQ | B10: 1 | C10: Earnings momentum slowing into 2H (Q1 and Q2 2026 statements) | D10: Down
A11: Fee income +55%, securities gains +42% not repeatable | B11: 1 | C11: Rahn is 33% of fee income; part of 1H26 income is one-off or concentrated | D11: Down
A12: Recoveries -24% | B12: 1 | C12: Support to cost of credit is fading; Base impairment already normalises to 0.80% | D12: Down
A13: Related-party musyarakah financing +45% YTD | B13: 1 | C13: Concentration and governance watch item (Q2 statement) | D13: Down
A14: Macro: BI-Rate 5.75%, SUN 10Y 7.16%, rupiah, geopolitics | B14: 1 | C14: Group view; raises funding cost and credit risk (Antara, market data 1 Oct 2026) | D14: Down
A15: Financing +16.2% YoY (Aug-26), DPK +17.7% | B15: 1 | C15: Growth ahead of the 10-14% 2026 target (OJK Aug-26, Q2 statement) | D15: Up
A16: Cost of credit 0.62% in 1H26 vs guidance <0.84% | B16: 1 | C16: Asset quality better than guided (interim statement) | D16: Up
A17: CAR 22-24% after rights issue | B17: 1 | C17: Capital buffer funds growth and absorbs stress (Prospektus, Q2 statement) | D17: Up
A18: Payout rising from 20% toward 30% | B18: 1 | C18: Capital-return optionality (AR2025 dividend policy) | D18: Up
A19: Industry credit growth 8-12% (BI) and sharia share rising | B19: 1 | C19: Structural tailwind (AR2025 p.182) | D19: Up
A21: Weight on downside evidence | B21: =SUMIF(D8:D19,"Down",B8:B19) -> 7
A22: Weight on upside evidence | B22: =SUMIF(D8:D19,"Up",B8:B19) -> 5
A24: Step 3. Resulting probabilities
A25: Bear = (1 - Base) x down / (down + up) | B25: =(1-B5)*B21/(B21+B22) -> 0.29166667
A26: Base | B26: =B5 -> 0.5
A27: Bull = (1 - Base) x up / (down + up) | B27: =(1-B5)*B22/(B21+B22) -> 0.20833333
A28: Check: sums to 100% (must be 0) | B28: =B25+B26+B27-1 -> 0
A30: Why Bear carries more weight than Bull: (1) the Bull case needs five drivers to move favourably at once, while a bank credit-cycle shock moves them together on the downside; (2) the 1H26 beat came from items flagged as not repeatable; (3) macro and rate risk is placed here, in cash flows, not in the cost of equity. Equal weights (33/33/33) would ignore that asymmetry; 25/50/25 would ignore the dated downside evidence.

Sheet Damodaran_Audit
A1: Audit against Damodaran bank valuation, live on the integrated model (active scenario)
A3: 1. Structural checks (live) | B3: Value | G3: Reading
A4: Cost of equity year 1 / stable (C4) | B4: =Sheet1!E34 -> 0.11229724 | C4: =Sheet1!S378 -> 0.1225 | G4: Ke only, no WACC: consistent (debt is raw material for a bank)
A5: Risk-free, IDR (gross yield less default spread) | B5: =Sheet1!E24 -> 0.0556 | G5: Local-currency rf, CRP counted once inside ERP
A6: Terminal growth g (live) | B6: =Sheet1!E31 -> 0.045 | G6: =IF(B6>B5,"g above rf: reduce","g does not exceed rf: OK") -> g does not exceed rf: OK
A7: Terminal ROE = Ke + spread (Sheet1 row 39) | B7: =Sheet1!E382 -> 0.1425 | G7: Tied to Ke; evidence in sheet Terminal_ROE
A8: Excess return in perpetuity = terminal ROE - Ke | B8: =Sheet1!E382-Sheet1!S378 -> 0.02 | G8: Damodaran: stable-growth ROE should converge to Ke plus a modest spread
A9: Terminal P/B implied = (ROE - g)/(Ke - g) | B9: =(B7-B6)/(B4-B6) -> 1.4487964 | G9: Compare with the historical range in section 3 (1.8x to 2.9x year-end, 1.3x today)
A10: Residual-income terminal value share of RI equity value | B10: =Sheet1!E394/Sheet1!E395 -> 0.15483532 | G10: Share of RI value from the terminal excess return
A11: DDM terminal value share of DDM value | B11: =Sheet1!E388 -> 0.75482218 | G11: Above about 75% means DDM is mostly terminal assumption
A12: Sustainable terminal payout = 1 - g/ROE | B12: =Sheet1!E383 -> 0.68421053 | G12: Used by the DDM terminal value
A13: Policy payout FY35E (input) | B13: =Sheet1!S108 -> 0.65 | G13: =IF(B13<B12,"Policy payout below sustainable payout: excess capital retained","Policy payout at or above sustainable payout") -> Policy payout below sustainable payout: excess capital retained
A14: CAR FY26E | B14: =Sheet1!J328 -> 0.22000884 | G14: Target floor in Sheet1!E35
A15: CAR FY30E | B15: =Sheet1!N328 -> 0.2565125 | G15: Rising CAR = capital over-retained
A16: CAR FY35E | B16: =Sheet1!S328 -> 0.26696653
A17: Excess capital FY35E over target (Rp bn) | B17: =Sheet1!S329 -> 38820.258 | G17: RIM assumes this earns full ROE; FCFE would distribute it
A18: DDM vs RI gap | B18: =Sheet1!E418 -> 0 | G18: =IF(ABS(B18)>0.25,"Above the 25% model tolerance: master check flags it","Within tolerance") -> Within tolerance
A20: 3. BRIS share price history (annual reports 2021-2025, year-end close) and market-implied Ke
A21: Period end | B21: Close (IDR) | C21: BVPS (IDR) | D21: P/B | E21: P/E (trailing) | F21: Implied Ke*
A22: Dec-2021 | B22: 1780 | C22: 608 | D22: 2.93 | E22: 24.2
A23: Dec-2022 | B23: 1290 | C23: 726 | D23: 1.78 | E23: 14 | F23: 0.106
A24: Dec-2023 | B24: 1740 | C24: 840 | D24: 2.07 | E24: 14.1 | F24: 0.1047
A25: Dec-2024 | B25: 2730 | C25: 976 | D25: 2.8 | E25: 18 | F25: 0.0951
A26: Dec-2025 | B26: 2230 | C26: 1126 | D26: 1.98 | E26: 13.6 | F26: 0.106
A27: 16 Oct 2026 (price; BVPS at 30 Jun 2026) | B27: =Sheet1!E20 -> 1095 | C27: =Sheet1!I464 -> 1106.4695 | D27: =B27/C27 -> 0.98963411 | E27: =B27/Sheet1!F464 -> 6.0773673 | F27: =Sheet1!E31+(Sheet1!J464-Sheet1!E31)/D27 -> 0.16261615
A29: *Implied Ke = g + (ROE - g)/PB. Rows 22-26: annual reports, g = 5.5%, trailing ROE of that year; Dec-2021 P/E uses 41.1bn shares (pre rights issue). Row 27 is live: Sheet1 E31 for g, ROE 1H26 annualised and BVPS at 30 Jun 2026.
A30: Annualised volatility from 19 quarterly closes (Q1-21 to Q4-25): about 32% (understated versus daily data). Only post-merger history (2021 onward) is comparable; BRIsyariah before Feb-2021 is a different entity.
A31: IHSG and peer monthly prices are now in sheets Prices, Returns and Beta (60m beta BRIS 0.69, SE about 0.29). Sharia peers BANK and PNBS not covered.

Sheet Driver_Check
A1: Driver check: template drivers vs evidence from AR2025 and 1H26 interim statements
A2: History and FY26E/FY30E of the template are live from Sheet1 (active scenario). 1H26 run-rate, team-model Base and evidence text are static from the team model v9. Positive gap = template higher than team evidence.
A4: Driver | B4: FY22A | C4: FY23A | D4: FY24A | E4: FY25A | F4: 1H26 run-rate (static) | G4: Pre-merge team model Base FY26E | H4: Template FY26E | I4: Gap FY26E | J4: Pre-merge team model Base FY30E | K4: Template FY30E | L4: Reading | M4: Evidence (AR2025, interim statements) | N4: External factors | O4: Pre-merge team model verdict (against v9 Base)
A5: Total asset growth | B5: =Sheet1!F169/Sheet1!E169-1 -> 0.15242999 | C5: =Sheet1!G169/Sheet1!F169-1 -> 0.15666591 | D5: =Sheet1!H169/Sheet1!G169-1 -> 0.15550132 | E5: =Sheet1!I169/Sheet1!H169-1 -> 0.1164427 | F5: 0.16 | G5: 0.13 | H5: =Sheet1!J169/Sheet1!I169-1 -> 0.1232986 | I5: =H5-G5 -> -0.0067013963 | J5: 0.09 | K5: =Sheet1!N169/Sheet1!M169-1 -> 0.10098853 | L5: =IF(ABS(I5)>0.02,"Review FY26E: template "&IF(I5>0,"higher","lower")&" than team evidence",IF(ABS(K5-J5)>0.04,"Review FY30E: template "&IF(K5>J5,"higher","lower")&" than team evidence","Within tolerance")) -> Within tolerance | M5: Assets grew 15.2%, 15.7%, 15.6% and 11.6% in FY22-25. Jun-26 assets of Rp464.5tn are +16% YoY (1H26 results). Gross financing +16.2% YoY and deposits +17.7% YoY at Aug-26. AR2025 (p.236) guides financing growth of 10-14% for 2026, so Aug-26 is above the top of range. Assets are seasonal: Dec-24 408.6tn, Jun-25 about 400tn (derived from the 16% YoY), Dec-25 456.2tn. FY26E of 515.5tn needs +11% in 2H26 versus +14% in 2H25. Fade to 9% reflects scale and CAR of 20.4% (Jun-26); the planned rights issue (Q1 2027) supports growth capacity. | N5: Bank Indonesia projects bank credit growth of 8-12% in 2026 (AR2025 p.182). BSI projects industry sharia assets of Rp1,205tn in 2026 (+12.9% on Rp1,067.7tn). OJK: sharia financing +11.61% YoY at Aug-26. BSI holds about 43% of industry assets and gains share (42.7% in 2025). Headwinds: BI-Rate held at 5.75% in Sep-26 (tight liquidity, rupiah pressure) and spin-offs of sharia units create new competitors. Bear 9% equals 2025 industry growth of 8.9% (share gains stop). Bull 16% equals the Jun-26 YoY pace. | O5: Supported. Keep Base 13% fading to 9%.
A6: HBH / average assets | B6: =Sheet1!F143/AVERAGE(Sheet1!F169,Sheet1!E169) -> 0.054606862 | C6: =Sheet1!G143/AVERAGE(Sheet1!G169,Sheet1!F169) -> 0.049316904 | D6: =Sheet1!H143/AVERAGE(Sheet1!H169,Sheet1!G169) -> 0.045679163 | E6: =Sheet1!I143/AVERAGE(Sheet1!I169,Sheet1!H169) -> 0.044239022 | F6: 0.042178674 | G6: 0.042 | H6: =Sheet1!J143/AVERAGE(Sheet1!J169,Sheet1!I169) -> 0.043622104 | I6: =H6-G6 -> 0.0016221045 | J6: 0.041 | K6: =Sheet1!N143/AVERAGE(Sheet1!N169,Sheet1!M169) -> 0.046963169 | L6: =IF(ABS(I6)>0.0015,"Review FY26E: template "&IF(I6>0,"higher","lower")&" than team evidence",IF(ABS(K6-J6)>0.003,"Review FY30E: template "&IF(K6>J6,"higher","lower")&" than team evidence","Within tolerance")) -> Review FY26E: template higher than team evidence | M6: Ratio fell from 5.46% (FY22) to 4.42% (FY25), about 25-50bp a year. In 1H26 HBH grew only 2.0% YoY (Rp9.71tn vs Rp9.52tn) while assets grew about 16%. Income from sales and purchases fell 7.7%; third-party share fell 6.6%; profit-sharing income rose 17.5%. Reported NIM was about 5.4% in 1H26 (-31bp YoY) against AR2025 guidance of above 5.50% (p.236). Financing yield fell about 77bp and cost of funds fell about 49bp (2.19%-2.30%). Mix shifts to gold-backed financing and securities (Rp61tn, mostly related party), which carry lower yields. Original Base of 4.30% implied HBH +9% for FY26E, needing +16% YoY in 2H26. | N6: BI-Rate was held at 5.75% in Sep-26, while the AR2025 macro assumption was 4.25%. Rate relief that would lift margins is not in sight. Deposit competition from state banks and digital banks keeps funding costs sticky. Murabahah is mostly fixed-rate, so repricing lags. Bear -0.2pp reflects continued yield compression; Bull +0.1pp reflects cost-of-fund gains. | O6: Not supported at 4.30%. Revised Base to 4.20%, fading to 4.10%.
A7: Other operating income / average assets | B7: =Sheet1!F144/AVERAGE(Sheet1!F169,Sheet1!E169) -> 0.012963248 | C7: =Sheet1!G144/AVERAGE(Sheet1!G169,Sheet1!F169) -> 0.012753347 | D7: =Sheet1!H144/AVERAGE(Sheet1!H169,Sheet1!G169) -> 0.0145794 | E7: =Sheet1!I144/AVERAGE(Sheet1!I169,Sheet1!H169) -> 0.01604197 | F7: 0.017694858 | G7: 0.0172 | H7: =Sheet1!J144/AVERAGE(Sheet1!J169,Sheet1!I169) -> 0.017903037 | I7: =H7-G7 -> 0.00070303739 | J7: 0.0162 | K7: =Sheet1!N144/AVERAGE(Sheet1!N169,Sheet1!M169) -> 0.018069785 | L7: =IF(ABS(I7)>0.001,"Review FY26E: template "&IF(I7>0,"higher","lower")&" than team evidence",IF(ABS(K7-J7)>0.002,"Review FY30E: template "&IF(K7>J7,"higher","lower")&" than team evidence","Within tolerance")) -> Within tolerance | M7: Ratio rose from 1.30% (FY22) to 1.60% (FY25) and 1.77% annualised in 1H26. 1H26: fee income +55% (Rp2.98tn vs Rp1.92tn), securities gains +42%, recoveries -24%. Fee-based income reached Rp5.6tn at Aug-26 (+36.3% YoY, 23.1% of revenue). Gold business +81% YoY with 1.22m gold customers. Quality flags from FY25: Rahn (gold pawn) is 33% of fee income, securities gains are 8.1% of PPOP, recoveries cover 55% of impairment. Base sits below the 1H26 run-rate because securities gains and recoveries do not repeat at this pace. | N7: Gold price and bullion regulation drive Rahn and gold instalment fees. Digital adoption (24.3m customers, BYOND) and hajj-related flows (7.69m hajj customers) support fee growth. Interest-rate moves drive securities gains: valuation losses already hit OCI in 1H26 (-Rp0.78tn). Bear -0.1pp, Bull +0.1pp. | O7: Base 1.62% was below run-rate. Revised Base to 1.72%, fading to 1.62%. Net revenue / assets is unchanged at 5.92%.
A8: Cost-to-income | B8: =Sheet1!F149/Sheet1!F145 -> 0.51292945 | C8: =Sheet1!G149/Sheet1!G145 -> 0.50086417 | D8: =Sheet1!H149/Sheet1!H145 -> 0.51353393 | E8: =Sheet1!I149/Sheet1!I145 -> 0.52562269 | F8: 0.52624585 | G8: 0.545 | H8: =Sheet1!J149/Sheet1!J145 -> 0.545 | I8: =H8-G8 -> 0 | J8: 0.52 | K8: =Sheet1!N149/Sheet1!N145 -> 0.505 | L8: =IF(ABS(I8)>0.01,"Review FY26E: template "&IF(I8>0,"higher","lower")&" than team evidence",IF(ABS(K8-J8)>0.02,"Review FY30E: template "&IF(K8>J8,"higher","lower")&" than team evidence","Within tolerance")) -> Within tolerance | M8: CIR was 51.3%, 50.1%, 51.4%, 52.6% in FY22-25. 1H26 opex grew 17.5% (G&A +19.1%, salaries +14.9%) against net revenue +10.5%; CIR 52.6% vs 49.5% in 1H25. Seasonality: 2H25 CIR was 55.4%, so FY26 at the same pattern would be near 55%. AR2025 reports 52.13% on the OJK basis (different definition; note it). Original Base of 53.5% needed opex growth to drop to +8% YoY in 2H26. Technology and digital investment (BYOND migration, cyber security after the 2023 ransomware incident) keep costs high near term; operating leverage arrives only as revenue per asset stabilises. | N8: Wage and general inflation (AR2025 assumes 2.34% CPI) is below BSI cost growth, so the gap is investment-driven, not inflation. Regulatory and cyber compliance costs are rising industry-wide. Bear +1.5pp, Bull -1.0pp. | O8: Not supported at 53.5%. Revised Base to 54.5%, improving 0.75pp a year to 52.0%.
A9: Impairment / average gross financing | B9: =Sheet1!F151/AVERAGE(Sheet1!F212,Sheet1!E212) -> 0.019782831 | C9: =Sheet1!G151/AVERAGE(Sheet1!G212,Sheet1!F212) -> 0.011706973 | D9: =Sheet1!H151/AVERAGE(Sheet1!H212,Sheet1!G212) -> 0.0073009944 | E9: =Sheet1!I151/AVERAGE(Sheet1!I212,Sheet1!H212) -> 0.0078916871 | F9: 0.006443979 | G9: 0.007 | H9: =Sheet1!J151/AVERAGE(Sheet1!J212,Sheet1!I212) -> 0.007 | I9: =H9-G9 -> 0 | J9: 0.008 | K9: =Sheet1!N151/AVERAGE(Sheet1!N212,Sheet1!M212) -> 0.0075 | L9: =IF(ABS(I9)>0.001,"Review FY26E: template "&IF(I9>0,"higher","lower")&" than team evidence",IF(ABS(K9-J9)>0.002,"Review FY30E: template "&IF(K9>J9,"higher","lower")&" than team evidence","Within tolerance")) -> Within tolerance | M9: Ratio fell from 1.98% (FY22) to 0.73-0.79% (FY24-25). 1H26 annualised 0.64% (cost of credit about 0.6%). AR2025 guidance is cost of credit below 0.84% (p.236). Early adoption of PSAK 413 (expected credit loss) raised allowance coverage from 3.5% to 4.5% of gross financing and cut equity by Rp3.0tn, so reserves are front-loaded. NPF gross about 1.8% (stable), loan-at-risk 8.0% (from 8.5%), LAR coverage 55%. Offsets: recoveries covered 55% of FY25 impairment and fell 24% in 1H26, so net cost rises as they fade. Related-party musyarakah financing grew 45% YTD (Rp26.1tn to Rp37.9tn), a concentration to watch. | N9: Debtor stress from the 5.75% BI-Rate and weak rupiah. Consumer book (Rp189tn, mostly payroll-based ASN) is stable. State-linked wholesale borrowers carry policy risk. Bear 1.0% = 2020s stress-like normalisation; Bull 0.6% = current run-rate. | O9: Supported. Keep Base 0.70% rising to 0.80%.
A10: Dividend payout (on prior-year net income) | B10: =IFERROR(Sheet1!F339/Sheet1!E154,"") -> 0.25 | C10: =IFERROR(Sheet1!G339/Sheet1!F154,"") -> 0.1 | D10: =IFERROR(Sheet1!H339/Sheet1!G154,"") -> 0.15 | E10: =IFERROR(Sheet1!I339/Sheet1!H154,"") -> 0.15 | F10: 0.2 | G10: 0.2 | H10: =IFERROR(Sheet1!J339/Sheet1!I154,"") -> 0.2 | I10: =H10-G10 -> 0 | J10: 0.3 | K10: =IFERROR(Sheet1!N339/Sheet1!M154,"") -> 0.3 | L10: =IF(ABS(I10)>0.03,"Review FY26E: template "&IF(I10>0,"higher","lower")&" than team evidence",IF(ABS(K10-J10)>0.06,"Review FY30E: template "&IF(K10>J10,"higher","lower")&" than team evidence","Within tolerance")) -> Within tolerance | M10: Payout was 25%, 10%, 15%, 15% in FY22-25 and 20% in 2026 (Rp32.81 per share, paid Jun-26). CAR is 20.41% (Jun-26) against a 12.5% floor with buffer and an 18% internal target. Base rises 2.5pp a year to 30%. A rights issue of up to 6.8bn shares is planned (RUPSLB 15 Oct 2026, execution Q1 2027), which argues against faster payout increases. | N10: State shareholders (Danantara-linked banks) favour higher payout; large state banks pay far more than BSI. The same path is used in all scenarios, so payout does not drive the Bear/Bull spread. | O10: Judgement, low value impact (DDM weight 15%). Keep.
A11: ROE on average equity / terminal ROE | B11: =Sheet1!F347 -> 0.14559142 | C11: =Sheet1!G347 -> 0.15789974 | D11: =Sheet1!H347 -> 0.1672435 | E11: =Sheet1!I347 -> 0.15604034 | F11: 0.16625882 | G11: 0.15059693 | H11: =Sheet1!J347 -> 0.15199023 | I11: =H11-G11 -> 0.001393294 | J11: 0.14 | K11: =Sheet1!N347 -> 0.15271595 | L11: =IF(ABS(I11)>0.01,"Review FY26E: template "&IF(I11>0,"higher","lower")&" than team evidence",IF(ABS(K11-J11)>0.02,"Review FY30E: template "&IF(K11>J11,"higher","lower")&" than team evidence","Within tolerance")) -> Within tolerance | M11: ROE was 14.6%, 15.8%, 16.7%, 15.6% in FY22-25 (net income / average equity; AR2025 reports 16.85% on the OJK basis). 1H26 annualised is higher because equity was reset down by PSAK 413. Terminal ROE of 14% sits just above Ke (13.85%), meaning excess return fades to almost zero. Bear 12% is below Ke (value destruction); Bull 16% matches the FY23-25 range. Sensitivity from the v3 grid (beta 1.00): each 1pp of terminal ROE is worth about Rp135 per share (12%: 1,044; 14%: 1,314; 16%: 1,587). | N11: Competitive convergence is the argument: HBH / assets has fallen every year since FY22, fee growth cannot be extrapolated, and a Q1-2027 rights issue dilutes ROE until deployed. Counter-argument: BSI leads its niche with about 43% share and growing CASA, so a higher terminal ROE is arguable. This is the second most sensitive input after beta. | O11: Judgement, conservative. Keep 14% as Base and show the 12-16% range.
A13: Tolerances (FY30E allowed twice the FY26E band): asset growth 2pp, HBH and other income per assets 0.15pp and 0.10pp, CIR 1pp, impairment 0.10pp, payout 3pp, ROE 1pp. Payout in the template is measured as dividends paid over prior-year net profit; FY22A-FY25A columns use the same definition. The two largest items to settle are CIR (52.5% template vs 54.5% team evidence) and total financing growth (14.4% vs 13%).

Sheet CF_Direct
B1: 2c-bis. Cash flow statement - DIRECT method, BSI reporting format (Rp bn)
